Workbook

Sheet Sheet1
A1: 45260 | B1: 45262 | C1: 45262 | D1: 45267 | E1: 45267 | F1: 45269 | G1: 45274 | H1: 45274 | I1: 45654 | J1: 45654
A2: Young Link | B2: King Dedede | C2: Samus | D2: Byleth | E2: Chrom | F2: Pichu | G2: Dr. Mario | H2: King Dedede | I2: Corrin | J2: Samus
A3: Zero Suit Samus | B3: Mega Man | C3: Ike | D3: Samus | E3: Terry | F3: Byleth | G3: Mii Swordfighter | H3: Mii Brawler | I3: Samus | J3: Mega Man
A4: Little Mac | B4: Kirby | C4: Mega Man | D4: King Dedede | E4: Bayonetta | F4: Isabelle | G4: Incineroar | H4: Mii Gunner | I4: Mega Man | J4: Lucas
A5: Mario | B5: Isabelle | C5: Jigglypuff | D5: Cloud | E5: King Dedede | F5: Sora | G5: Wario | H5: Bayonetta | I5: Lucas | J5: Zero Suit Samus
A6: King Dedede | B6: Byleth | C6: Ken | D6: Terry | E6: Byleth | F6: Samus | G6: King Dedede | H6: Wii Fit Trainer | I6: Villager | J6: Robin
A7: Lucas | B7: Pikachu | C7: Joker | D7: Captain Falcon | E7: Samus | F7: Terry | G7: Young Link | H7: Young Link | I7: Luigi | J7: Link
A8: Dr. Mario | B8: Ken | C8: King Dedede | D8: Ken | E8: Villager | F8: Pokemon Trainer | G8: Samus | H8: Isabelle | I8: Fox | J8: Corrin
A9: Meta Knight | B9: Diddy Kong | C9: R.O.B. | D9: Young Link | E9: Little Mac | F9: Dark Samus | G9: Meta Knight | H9: Samus | I9: Mii Swordfighter | J9: Bayonetta
A12: Character | B12: Top 8's | C12: Trophies | D12: History | E12: Avg Position | F12: Total
A13: Banjo-Kazooie | B13: 5 | C13: 0 | D13: 4,7,8,2,3 | E13: 4.8 | F13: 24 | J13: Character | K13: Top 8's | L13: Trophies | M13: Avg Position | N13: Trophy Rate
A14: Bayonetta | B14: 18 | C14: 2 | D14: 3,6,2,7,6,4,2,1,3,2,8,7,6,1,2,3,4,8 | E14: 4.17 | F14: 75 | J14: Banjo-Kazooie | K14: 5 | L14: 0 | M14: 4.8 | N14: 0
A15: Bowser | B15: 4 | C15: 0 | D15: 6,5,4,8 | E15: 5.75 | F15: 23 | J15: Bayonetta | K15: 18 | L15: 2 | M15: 4.17 | N15: 0.11
A16: Bowser Jr. | B16: 3 | C16: 0 | D16: 6,6,5 | E16: 5.67 | F16: 17 | J16: Bowser | K16: 4 | L16: 0 | M16: 5.75 | N16: 0
A17: Byleth | B17: 22 | C17: 7 | D17: 1,2,2,6,3,8,2,4,1,1,1,1,1,3,3,3,2,7,5,1,5,2 | E17: 2.91 | F17: 64 | J17: Bowser Jr. | K17: 3 | L17: 0 | M17: 5.67 | N17: 0
A18: Captain Falcon | B18: 30 | C18: 5 | D18: 1,1,2,5,1,6,6,8,4,5,8,1,4,2,7,2,8,2,5,7,2,4,3,1,7,2,4,7,8,6 | E18: 4.33 | F18: 129 | J18: Byleth | K18: 22 | L18: 7 | M18: 2.91 | N18: 0.32
A19: Cloud | B19: 11 | C19: 2 | D19: 1,5,8,8,1,2,6,6,6,2,4 | E19: 4.45 | F19: 49 | J19: Captain Falcon | K19: 30 | L19: 5 | M19: 4.3 | N19: 0.17
A20: Chrom | B20: 1 | C20: 1 | D20: 1 | E20: 1 | F20: 1 | J20: Cloud | K20: 11 | L20: 2 | M20: 4.45 | N20: 0.18
A21: Corrin | B21: 33 | C21: 3 | D21: 4,2,3,2,2,3,1,3,1,2,5,7,8,3,4,8,4,7,4,5,6,2,2,2,8,3,7,6,4,7,7,1,7 | E21: 4.24 | F21: 140 | J21: Corrin | K21: 33 | L21: 3 | M21: 4.24 | N21: 0.09
A22: Daisy | B22: 3 | C22: 0 | D22: 2,6,8 | E22: 5.33 | F22: 16 | J22: Donkey Kong | K22: 30 | L22: 3 | M22: 5.23 | N22: 0.1
A23: Diddy Kong | B23: 3 | C23: 1 | D23: 1,8,8 | E23: 5.67 | F23: 17 | J23: Falco | K23: 6 | L23: 0 | M23: 3.67 | N23: 0
A24: Donkey Kong | B24: 30 | C24: 3 | D24: 7,4,7,7,4,5,8,4,2,6,1,6,5,6,1,6,7,7,6,5,7,5,7,1,3,8,2,4,8,8 | E24: 5.23 | F24: 157 | J24: Fox | K24: 11 | L24: 1 | M24: 5.82 | N24: 0.09
A25: Dr. Mario | B25: 3 | C25: 1 | D25: 6,7,1 | E25: 4.67 | F25: 14 | J25: Ganondorf | K25: 26 | L25: 3 | M25: 5.31 | N25: 0.12
A26: Duck Hunt | B26: 3 | C26: 0 | D26: 3,4,5 | E26: 4 | F26: 12 | J26: Greninja | K26: 5 | L26: 1 | M26: 5 | N26: 0.2
A27: Falco | B27: 6 | C27: 0 | D27: 4,2,4,2,3,7 | E27: 3.67 | F27: 22 | J27: Hero | K27: 4 | L27: 0 | M27: 4.25 | N27: 0
A28: Fox | B28: 11 | C28: 1 | D28: 8,6,8,8,4,8,4,4,1,6,7 | E28: 5.82 | F28: 64 | J28: Ice-Climbers | K28: 3 | L28: 0 | M28: 6 | N28: 0
A29: Ganondorf | B29: 26 | C29: 3 | D29: 8,6,1,5,6,3,7,5,8,1,1,7,8,2,6,4,8,6,4,5,5,8,6,7,3 | E29: 5.31 | F29: 138 | J29: Incineroar | K29: 7 | L29: 1 | M29: 4.43 | N29: 0.14
A30: Greninja | B30: 5 | C30: 1 | D30: 6,1,6,6,6 | E30: 5 | F30: 25 | J30: Inkling | K30: 3 | L30: 0 | M30: 4 | N30: 0
A31: Hero | B31: 4 | C31: 0 | D31: 2,3,5,7 | E31: 4.25 | F31: 17 | J31: Isabelle | K31: 7 | L31: 3 | M31: 3.29 | N31: 0.43
A32: Ike | B32: 3 | C32: 0 | D32: 8,4,2 | E32: 4.67 | F32: 14 | H32: * | J32: Jigglypuff | K32: 13 | L32: 0 | M32: 4.62 | N32: 0
A33: Ice-Climbers | B33: 3 | C33: 0 | D33: 7,4,7 | E33: 6 | F33: 18 | J33: Joker | K33: 8 | L33: 2 | M33: 4.5 | N33: 0.25
A34: Incineroar | B34: 7 | C34: 1 | D34: 1,5,4,6,6,4,3 | E34: 4.43 | F34: 31 | J34: Ken | K34: 9 | L34: 0 | M34: 6.11 | N34: 0
A35: Inkling | B35: 3 | C35: 0 | D35: 2,6,4 | E35: 4 | F35: 12 | J35: King Dedede | K35: 61 | L35: 13 | M35: 4.11 | N35: 0.21
A36: Isabelle | B36: 7 | C36: 3 | D36: 1,1,1,6,4,3,7 | E36: 3.29 | F36: 23 | J36: King K Rool | K36: 10 | L36: 1 | M36: 5 | N36: 0.1
A37: Jigglypuff | B37: 13 | C37: 0 | D37: 2,4,2,7,8,8,8,7,2,2,2,4,4 | E37: 4.62 | F37: 60 | J37: Kirby | K37: 24 | L37: 3 | M37: 4.29 | N37: 0.13
A38: Joker | B38: 8 | C38: 2 | D38: 8,1,3,5,8,4,1,6 | E38: 4.5 | F38: 36 | J38: Link | K38: 6 | L38: 1 | M38: 4.17 | N38: 0.17
A39: Kazuya | B39: 3 | C39: 1 | D39: 3,1,6 | E39: 3.33 | F39: 10 | J39: Lucario | K39: 11 | L39: 2 | M39: 3.45 | N39: 0.18
A40: Ken | B40: 9 | C40: 0 | D40: 8,5,3,7,8,5,7,5,7 | E40: 6.11 | F40: 55 | J40: Luigi | K40: 8 | L40: 0 | M40: 4.75 | N40: 0
A41: King Dedede | B41: 61 | C41: 13 | D41: 5,1,1,8,3,3,4,4,7,1,8,3,4,5,4,3,1,1,3,3,1,4,6,1,2,1,1,4,8,1,3,8,6,1,3,5,7,7,5,8,7,7,4,6,4,8,6,7,8,2,2,4,5,4,1,7,5,3,4,5,1 | E41: 4.11 | F41: 251 | J41: Mario | K41: 16 | L41: 0 | M41: 5.38 | N41: 0
A42: King K Rool | B42: 10 | C42: 1 | D42: 7,8,7,3,4,7,6,1,5,2 | E42: 5 | F42: 50 | J42: Mega Man | K42: 21 | L42: 3 | M42: 3.24 | N42: 0.14
...

Sheet Sheet2
A1: Character | B1: Top 8's | C1: Trophies | D1: Avg Position | E1: Trophy Rate | H1: Character | I1: Top 8's | J1: Trophies | K1: Avg Position | L1: Trophy Rate | O1: Character | P1: Top 8's | Q1: Trophies | R1: Avg Position | S1: Trophy Rate
A2: Isabelle | B2: 6 | C2: 3 | D2: 2.67 | E2: 0.5 | H2: Byleth | I2: 22 | J2: 7 | K2: 2.91 | L2: 0.32 | O2: Byleth | P2: 22 | Q2: 7 | R2: 2.91 | S2: 0.32
A3: Byleth | B3: 22 | C3: 7 | D3: 2.91 | E3: 0.32 | H3: Isabelle | I3: 7 | J3: 3 | K3: 3.29 | L3: 0.43 | M3: ▼1 | O3: Mega Man | P3: 21 | Q3: 3 | R3: 3.24 | S3: 0.14 | T3: ▲1
A4: Mega Man | B4: 19 | C4: 3 | D4: 3.32 | E4: 0.17 | H4: Mega Man | I4: 19 | J4: 3 | K4: 3.32 | L4: 0.17 | O4: Isabelle | P4: 7 | Q4: 3 | R4: 3.29 | S4: 0.43 | T4: ▼1
A5: Kazuya | B5: 3 | C5: 1 | D5: 3.33 | E5: 0.33 | H5: Kazuya | I5: 3 | J5: 1 | K5: 3.33 | L5: 0.33 | O5: Kazuya | P5: 3 | Q5: 1 | R5: 3.33 | S5: 0.33
A6: Marth | B6: 5 | C6: 1 | D6: 3.4 | E6: 0.2 | H6: Marth | I6: 5 | J6: 1 | K6: 3.4 | L6: 0.2 | O6: Marth | P6: 5 | Q6: 1 | R6: 3.4 | S6: 0.2
A7: Lucario | B7: 11 | C7: 2 | D7: 3.45 | E7: 0.18 | H7: Lucario | I7: 11 | J7: 2 | K7: 3.45 | L7: 0.18 | O7: Lucario | P7: 11 | Q7: 2 | R7: 3.45 | S7: 0.18
A8: Falco | B8: 6 | C8: 0 | D8: 3.67 | E8: 0 | H8: Falco | I8: 6 | J8: 0 | K8: 3.67 | L8: 0 | O8: Falco | P8: 6 | Q8: 0 | R8: 3.67 | S8: 0
A9: Wii Fit Trainer | B9: 3 | C9: 0 | D9: 3.67 | E9: 0 | F9: ▲1 | H9: Pit | I9: 3 | J9: 1 | K9: 3.67 | L9: 0.33 | M9: ▲1 | O9: Pit | P9: 3 | Q9: 1 | R9: 3.67 | S9: 0.33
A10: Pit | B10: 3 | C10: 1 | D10: 3.67 | E10: 0.33 | F10: ▲1 | H10: Link | I10: 5 | J10: 1 | K10: 3.8 | L10: 0.2 | O10: Piranha Plant | P10: 6 | Q10: 0 | R10: 3.83 | S10: 0 | T10: ▲1
A11: Link | B11: 5 | C11: 1 | D11: 3.8 | E11: 0.2 | F11: ▲1 | H11: Piranha Plant | I11: 6 | J11: 0 | K11: 3.83 | L11: 0 | O11: Villager | P11: 20 | Q11: 5 | R11: 3.9 | S11: 0.25 | T11: ▲1
A12: Piranha Plant | B12: 6 | C12: 0 | D12: 3.83 | E12: 0 | F12: ▲1 | H12: Villager | I12: 19 | J12: 5 | K12: 3.84 | L12: 0.26 | M12: ▲1 | O12: Terry | P12: 22 | Q12: 5 | R12: 3.95 | S12: 0.23 | T12: ▲2
A13: Villager | B13: 19 | C13: 5 | D13: 3.84 | E13: 0.26 | F13: ▼4 | H13: Bayonetta | I13: 17 | J13: 2 | K13: 3.94 | L13: 0.12 | M13: ▲1 | O13: Inkling | P13: 3 | Q13: 0 | R13: 4 | S13: 0 | T13: ▲2
A14: Bayonetta | B14: 16 | C14: 2 | D14: 3.94 | E14: 0.13 | F14: ▲1 | H14: Terry | I14: 22 | J14: 5 | K14: 3.95 | L14: 0.23 | M14: ▲1 | O14: Palutena | P14: 3 | Q14: 0 | R14: 4 | S14: 0 | T14: ▲2
A15: Terry | B15: 22 | C15: 5 | D15: 3.95 | E15: 0.23 | F15: ▼1 | H15: Inkling | I15: 3 | J15: 0 | K15: 4 | L15: 0 | O15: Sephiroth | P15: 3 | Q15: 1 | R15: 4 | S15: 0.33 | T15: ▲2
A16: Inkling | B16: 3 | C16: 0 | D16: 4 | E16: 0 | H16: Palutena | I16: 3 | J16: 0 | K16: 4 | L16: 0 | O16: Wii Fit Trainer | P16: 4 | Q16: 0 | R16: 4 | S16: 0 | T16: ▲2
A17: Palutena | B17: 3 | C17: 0 | D17: 4 | E17: 0 | H17: Sephiroth | I17: 3 | J17: 1 | K17: 4 | L17: 0.33 | O17: Zelda | P17: 4 | Q17: 1 | R17: 4 | S17: 0.25 | T17: ▲2
A18: Sephiroth | B18: 3 | C18: 1 | D18: 4 | E18: 0.33 | H18: Wii Fit Trainer | I18: 4 | J18: 0 | K18: 4 | L18: 0 | M18: ▼6 | O18: Duck Hunt | P18: 3 | Q18: 0 | R18: 4 | S18: 0 | T18: ▲2
A19: Zelda | B19: 4 | C19: 1 | D19: 4 | E19: 0.25 | H19: Zelda | I19: 4 | J19: 1 | K19: 4 | L19: 0.25 | O19: Mii Swordfighter | P19: 3 | Q19: 0 | R19: 4 | S19: 0 | T19: New Mid
A20: Duck Hunt | B20: 3 | C20: 0 | D20: 4 | E20: 0 | H20: Duck Hunt | I20: 3 | J20: 0 | K20: 4 | L20: 0 | O20: King Dedede | P20: 61 | Q20: 13 | R20: 4.11 | S20: 0.21 | T20: ▲1
A21: Wario | B21: 8 | C21: 2 | D21: 4.13 | E21: 0.25 | F21: ▲1 | H21: King Dedede | I21: 61 | J21: 13 | K21: 4.11 | L21: 0.21 | M21: ▲1 | O21: Wario | P21: 9 | Q21: 2 | R21: 4.11 | S21: 0.22 | T21: ▲1
A22: King Dedede | B22: 59 | C22: 12 | D22: 4.15 | E22: 0.2 | F22: ▲1 | H22: Wario | I22: 9 | J22: 2 | K22: 4.11 | L22: 0.22 | O22: Bayonetta | P22: 18 | Q22: 2 | R22: 4.17 | S22: 0.11 | T22: ▼9💀
A23: Samus | B23: 54 | C23: 8 | D23: 4.17 | E23: 0.15 | F23: ▼2 | H23: Hero | I23: 4 | J23: 0 | K23: 4.25 | L23: 0 | M23: ▲1 | O23: Link | P23: 6 | Q23: 1 | R23: 4.17 | S23: 0.17 | T23: ▼13💀💀
A24: Hero | B24: 4 | C24: 0 | D24: 4.25 | E24: 0 | F24: ▲1 | H24: Toon Link | I24: 4 | J24: 0 | K24: 4.25 | L24: 0 | M24: ▲1 | O24: Samus | P24: 58 | Q24: 9 | R24: 4.19 | S24: 0.16 | T24: ▲3
A25: Toon Link | B25: 4 | C25: 0 | D25: 4.25 | E25: 0 | F25: ▲1 | H25: Corrin | I25: 31 | J25: 2 | K25: 4.26 | L25: 0.06 | M25: ▲1 | O25: Corrin | P25: 33 | Q25: 3 | R25: 4.24 | S25: 0.09
A26: Corrin | B26: 31 | C26: 2 | D26: 4.26 | E26: 0.06 | F26: ▲1 | H26: Kirby | I26: 24 | J26: 3 | K26: 4.29 | L26: 0.13 | M26: ▲1 | O26: Hero | P26: 4 | Q26: 0 | R26: 4.25 | S26: 0 | T26: ▼3
A27: Kirby | B27: 24 | C27: 3 | D27: 4.29 | E27: 0.13 | F27: ▲1 | H27: Samus | I27: 56 | J27: 8 | K27: 4.29 | L27: 0.14 | M27: ▼3 | O27: Toon Link | P27: 4 | Q27: 0 | R27: 4.25 | S27: 0 | T27: ▼3
A28: Sonic | B28: 7 | C28: 2 | D28: 4.29 | E28: 0.29 | F28: ▲1 | H28: Sonic | I28: 7 | J28: 2 | K28: 4.29 | L28: 0.29 | O28: Kirby | P28: 24 | Q28: 3 | R28: 4.29 | S28: 0.13 | T28: ▼2
A29: Captain Falcon | B29: 30 | C29: 5 | D29: 4.3 | E29: 0.17 | F29: ▼5 | H29: Captain Falcon | I29: 30 | J29: 5 | K29: 4.3 | L29: 0.17 | O29: Sonic | P29: 7 | Q29: 2 | R29: 4.29 | S29: 0.29 | T29: ▼1
A30: Mewtwo | B30: 3 | C30: 0 | D30: 4.33 | E30: 0 | H30: Mewtwo | I30: 3 | J30: 0 | K30: 4.33 | L30: 0 | O30: Captain Falcon | P30: 30 | Q30: 5 | R30: 4.3 | S30: 0.17 | T30: ▼1
A31: Princess Peach | B31: 9 | C31: 0 | D31: 4.44 | E31: 0 | H31: Incineroar | I31: 7 | J31: 1 | K31: 4.43 | L31: 0.14 | M31: ▲7 | O31: Mewtwo | P31: 3 | Q31: 0 | R31: 4.33 | S31: 0 | T31: ▼1
A32: Cloud | B32: 11 | C32: 2 | D32: 4.45 | E32: 0.18 | H32: Princess Peach | I32: 9 | J32: 0 | K32: 4.44 | L32: 0 | M32: ▼1 | O32: Lucas | P32: 3 | Q32: 0 | R32: 4.33 | S32: 0 | T32: New Mid
A33: Joker | B33: 8 | C33: 2 | D33: 4.5 | E33: 0.25 | H33: Cloud | I33: 11 | J33: 2 | K33: 4.45 | L33: 0.18 | M33: ▼1 | O33: Incineroar | P33: 7 | Q33: 1 | R33: 4.43 | S33: 0.14 | T33: ▼2
A34: Luigi | B34: 7 | C34: 0 | D34: 4.57 | E34: 0 | H34: Joker | I34: 8 | J34: 2 | K34: 4.5 | L34: 0.25 | M34: ▼1 | O34: Princess Peach | P34: 9 | Q34: 0 | R34: 4.44 | S34: 0 | T34: ▼2
A35: Mr. Game & Watch | B35: 7 | C35: 0 | D35: 4.57 | E35: 0 | H35: Luigi | I35: 7 | J35: 0 | K35: 4.57 | L35: 0 | M35: ▼1 | O35: Cloud | P35: 11 | Q35: 2 | R35: 4.45 | S35: 0.18 | T35: ▼2
A36: R.O.B. | B36: 10 | C36: 0 | D36: 4.6 | E36: 0 | H36: Mr. Game & Watch | I36: 7 | J36: 0 | K36: 4.57 | L36: 0 | M36: ▼1 | O36: Joker | P36: 8 | Q36: 2 | R36: 4.5 | S36: 0.25 | T36: ▼2
A37: Jigglypuff | B37: 13 | C37: 0 | D37: 4.62 | E37: 0 | H37: R.O.B. | I37: 10 | J37: 0 | K37: 4.6 | L37: 0 | M37: ▼1 | O37: Mr. Game & Watch | P37: 7 | Q37: 0 | R37: 4.57 | S37: 0 | T37: ▼1
A38: Incineroar | B38: 6 | C38: 1 | D38: 4.67 | E38: 0.17 | H38: Jigglypuff | I38: 13 | J38: 0 | K38: 4.62 | L38: 0 | M38: ▼1 | O38: R.O.B. | P38: 10 | Q38: 0 | R38: 4.6 | S38: 0 | T38: ▼1
A39: Yoshi | B39: 12 | C39: 1 | D39: 4.67 | E39: 0.08 | H39: Yoshi | I39: 12 | J39: 1 | K39: 4.67 | L39: 0.08 | O39: Jigglypuff | P39: 13 | Q39: 0 | R39: 4.62 | S39: 0 | T39: ▼1
A40: Ike | B40: 3 | C40: 0 | D40: 4.67 | E40: 0 | H40: Ike | I40: 3 | J40: 0 | K40: 4.67 | L40: 0 | O40: Yoshi | P40: 12 | Q40: 1 | R40: 4.67 | S40: 0.08 | T40: ▼1
...

Sheet Sheet3
A1: 44955 | B1: 44973 | C1: 44994 | D1: 45008 | E1: 45008 | F1: 45010 | G1: 45015 | H1: 45022 | I1: 45029 | J1: 45038 | K1: 45038 | L1: 45043 | M1: 45050 | N1: 45051 | O1: 45051 | P1: 45051 | Q1: 45057 | R1: 45057 | S1: 45059 | T1: 45059 | U1: 45059 | V1: 45059 | W1: 45059 | X1: 45064 | Y1: 45066 | Z1: 45066 | AA1: 45071 | AB1: 45078 | AC1: 45080 | AD1: 45080 | AE1: 45085 | AF1: 45087 | AG1: 45087 | AH1: 45092 | AI1: 45092 | AJ1: 45092
A2: Mega Man | B2: Captain Falcon | C2: Captain Falcon | D2: Kirby | E2: Captain Falcon | F2: King Dedede | G2: Wario | H2: King Dedede | I2: Sonic | J2: Villager | K2: Cloud | L2: Donkey Kong | M2: Corrin | N2: Ganondorf | O2: Corrin | P2: King Dedede | Q2: Donkey Kong | R2: King K Rool | S2: Ridley | T2: Yoshi | U2: Cloud | V2: Kirby | W2: Kirby | X2: Marth | Y2: Captain Falcon | Z2: Incineroar | AA2: Greninja | AB2: Villager | AC2: Ness | AD2: Diddy Kong | AE2: King Dedede | AF2: King Dedede | AG2: Samus | AH2: Snake | AI2: King Dedede | AJ2: Link
A3: Meta Knight | B3: Dark Pit | C3: Captain Falcon | D3: Corrin | E3: Luigi | F3: Mega Man | G3: Jigglypuff | H3: Corrin | I3: Mega Man | J3: Donkey Kong | K3: Meta Knight | L3: Corrin | M3: Jigglypuff | N3: Kirby | O3: Mario | P3: Samus | Q3: Corrin | R3: Palutena | S3: Pikachu | T3: Yoshi | U3: Ness | V3: Mii Swordfighter | W3: Princess Peach | X3: Rosalina | Y3: R.O.B. | Z3: Falco | AA3: Mario | AB3: Captain Falcon | AC3: Corrin | AD3: Corrin | AE3: Falco | AF3: Inkling | AG3: Samus | AH3: Captain Falcon | AI3: Bayonetta | AJ3: Captain Falcon
A4: Zelda | B4: Kirby | C4: Sonic | D4: Meta Knight | E4: Corrin | F4: Kirby | G4: Mewtwo | H4: Wario | I4: Greninja | J4: King Dedede | K4: King Dedede | L4: Corrin | M4: King K Rool | N4: Corrin | O4: Meta Knight | P4: Kirby | Q4: Duck Hunt | R4: King Dedede | S4: Mario | T4: Corrin | U4: Ganondorf | V4: Palutena | W4: Link | X4: R.O.B. | Y4: Richter | Z4: Shulk | AA4: King Dedede | AB4: Mario | AC4: Meta Knight | AD4: R.O.B. | AE4: Snake | AF4: Bayonetta | AG4: King Dedede | AH4: King Dedede | AI4: Ness | AJ4: Ryu
A5: Yoshi | B5: Donkey Kong | C5: Corrin | D5: Dark Samus | E5: Donkey Kong | F5: Samus | G5: Pikachu | H5: Donkey Kong | I5: Ridley | J5: Meta Knight | K5: Jigglypuff | L5: King Dedede | M5: King Dedede | N5: King K Rool | O5: Kirby | P5: Falco | Q5: Captain Falcon | R5: Duck Hunt | S5: King Dedede | T5: Yoshi | U5: Mewtwo | V5: Corrin | W5: Corrin | X5: King Dedede | Y5: Villager | Z5: Captain Falcon | AA5: Corrin | AB5: Ness | AC5: Kirby | AD5: Falco | AE5: Incineroar | AF5: Ness | AG5: Fox | AH5: Bowser | AI5: Wolf | AJ5: King Dedede
A6: Little Mac | B6: Rosalina | C6: King Dedede | D6: Captain Falcon | E6: Samus | F6: Donkey Kong | G6: Pichu | H6: Ken | I6: Ganondorf | J6: Ridley | K6: Luigi | L6: Bowser | M6: Cloud | N6: Donkey Kong | O6: Ganondorf | P6: Meta Knight | Q6: Corrin | R6: Captain Falcon | S6: Sonic | T6: Villager | U6: King Dedede | V6: Yoshi | W6: Donkey Kong | X6: Link | Y6: Ganondorf | Z6: Donkey Kong | AA6: Incineroar | AB6: Corrin | AC6: R.O.B. | AD6: Meta Knight | AE6: R.O.B. | AF6: Samus | AG6: Ness | AH6: Ness | AI6: Ken | AJ6: Mario
A7: Pac Man | B7: Mega Man | C7: Roy | D7: Dr. Mario | E7: Yoshi | F7: Yoshi | G7: Bowser | H7: Captain Falcon | I7: Captain Falcon | J7: Yoshi | K7: Donkey Kong | L7: Ganondorf | M7: Donkey Kong | N7: Mewtwo | O7: Pikachu | P7: Donkey Kong | Q7: King K Rool | R7: Donkey Kong | S7: Ganondorf | T7: Roy | U7: Donkey Kong | V7: Mario | W7: Yoshi | X7: Kirby | Y7: Fox | Z7: Greninja | AA7: Ridley | AB7: Corrin | AC7: Luigi | AD7: Ness | AE7: Ness | AF7: Bowser Jr. | AG7: Mario | AH7: Bayonetta | AI7: Snake | AJ7: Inkling
A8: Donkey Kong | B8: King K Rool | C8: Donkey Kong | D8: Donkey Kong | E8: Princess Peach | F8: Meta Knight | G8: Meta Knight | H8: Simon | I8: King K Rool | J8: Inkling | K8: Pikachu | L8: Mega Man | M8: Wolf | N8: King Dedede | O8: Jigglypuff | P8: King K Rool | Q8: Palutena | R8: Corrin | S8: Donkey Kong | T8: Donkey Kong | U8: Pikachu | V8: Villager | W8: Ganondorf | X8: Wolf | Y8: Donkey Kong | Z8: Corrin | AA8: Iceclimbers | AB8: Kirby | AC8: Ryu | AD8: Ridley | AE8: Captain Falcon | AF8: Mario | AG8: Simon | AH8: Mario | AI8: Shulk | AJ8: Bayonetta
A9: Sonic | B9: Zelda | C9: Ridley | D9: Fox | E9: Ness | F9: Ganondorf | G9: Donkey Kong | H9: King K Rool | I9: King Dedede | J9: Pikachu | K9: Yoshi | L9: Captain Falcon | M9: Ike | N9: Cloud | O9: Ken | P9: Cloud | Q9: King Dedede | R9: Corrin | S9: Samus | T9: Jigglypuff | U9: Kirby | V9: Corrin | W9: Jigglypuff | X9: Captain Falcon | Y9: Mario | Z9: Fox | AA9: Rosalina | AB9: R.O.B. | AC9: Mario | AD9: Fox | AE9: Rosalina | AF9: Richter | AG9: Jigglypuff | AH9: Sheik | AI9: Captain Falcon | AJ9: Snake
A12: 45094 | B12: 45099 | C12: 45101 | D12: 45106 | E12: 45108 | F12: 45115 | G12: 45115 | H12: 45115 | I12: 45115 | J12: 45115 | K12: 45120 | L12: 45120 | M12: 45134 | N12: 45134 | O12: 45136 | P12: 45136 | Q12: 45141 | R12: 45148 | S12: 45148 | T12: 45148 | U12: 45150 | V12: 45150 | W12: 45162 | X12: 45169 | Y12: 45176 | Z12: 45183 | AA12: 45185 | AB12: 45185 | AC12: 45197 | AD12: 45199 | AE12: 45204 | AF12: 45205 | AG12: 45205 | AH12: 45205 | AI12: 45206 | AJ12: 45206 | AK12: 45206 | AL12: 45206 | AM12: 45206
A13: Isabelle | B13: King Dedede | C13: Isabelle | D13: Joker | E13: King Dedede | F13: Samus | G13: King Dedede | H13: Ganondorf | I13: Ganondorf | J13: Villager | K13: King Dedede | L13: Bayonetta | M13: Captain Falcon | N13: Byleth | O13: Samus | P13: King Dedede | Q13: Donkey Kong | R13: Lucario | S13: Villager | T13: Villager | U13: Samus | V13: Samus | W13: Terry | X13: Samus | Y13: Terry | Z13: Villager | AA13: Kazuya | AB13: Sephiroth | AC13: Wolf | AD13: Byleth | AE13: Fox | AF13: Samus | AG13: Lucario | AH13: Meta Knight | AI13: Byleth | AJ13: Isabelle | AK13: Mega Man | AL13: Byleth | AM13: Zelda
A14: Toon Link | B14: Corrin | C14: Cloud | D14: King Dedede | E14: Captain Falcon | F14: King K. Rool | G14: Samus | H14: Snake | I14: Jigglypuff | J14: Cloud | K14: Bayonetta | L14: Link | M14: Ganondorf | N14: Bayonetta | O14: Kirby | P14: Captain Falcon | Q14: Toon Link | R14: Villager | S14: Samus | T14: Banjo-Kazooie | U14: Byleth | V14: Byleth | W14: Hero | X14: Mr. Game & Watch | Y14: Jigglypuff | Z14: Samus | AA14: Samus | AB14: Byleth | AC14: Villager | AD14: Piranha Plant | AE14: Simon | AF14: Piranha Plant | AG14: Jigglypuff | AH14: Yoshi | AI14: Daisy | AJ14: Mega Man | AK14: Lucario | AL14: Pikachu | AM14: Lucario
A15: Sheik | B15: Kirby | C15: Samus | D15: Corrin | E15: R.O.B. | F15: Lucario | G15: Princess Peach | H15: Falco | I15: Captain Falcon | J15: Samus | K15: Joker | L15: King Dedede | M15: Bayonetta | N15: Terry | O15: Wii Fit Trainer | P15: Ken | Q15: King Dedede | R15: Mega Man | S15: Mega Man | T15: Samus | U15: Pokemon Trainer | V15: Kazuya | W15: Samus | X15: Byleth | Y15: Samus | Z15: Marth | AA15: Lucario | AB15: Hero | AC15: Ness | AD15: Lucario | AE15: Terry | AF15: Mega Man | AG15: Wii Fit Trainer | AH15: Roy | AI15: Samus | AJ15: Donkey Kong | AK15: Samus | AL15: Samus | AM15: Marth
A16: Inkling | B16: Olimar | C16: R.O.B. | D16: Ice-Climbers | E16: Bayonetta | F16: Captain Falcon | G16: King Dedede | H16: Princess Peach | I16: Princess Peach | J16: Kirby | K16: Banjo-Kazooie | L16: Pichu | M16: Corrin | N16: Fox | O16: Ganondorf | P16: Meta Knight | Q16: Sephiroth | R16: Samus | S16: Mr. Game & Watch | T16: Ganondorf | U16: Wario | V16: Samus | W16: Captain Falcon | X16: Fox | Y16: Dark Samus | Z16: King Dedede | AA16: Terry | AB16: King Dedede | AC16: Byleth | AD16: Pac Man | AE16: Lucario | AF16: Ike | AG16: Terry | AH16: Ness | AI16: Villager | AJ16: Mario | AK16: Zelda | AL16: Luigi | AM16: Pokemon Trainer
A17: Mr. Game & Watch | B17: Captain Falcon | C17: Meta Knight | D17: Olimar | E17: King K. Rool | F17: Wii Fit Trainer | G17: R.O.B. | H17: Kirby | I17: Robin | J17: Toon Link | K17: Kirby | L17: Kirby | M17: Olimar | N17: Olimar | O17: Ryu | P17: Pichu | Q17: Kirby | R17: King Dedede | S17: Steve | T17: Steve | U17: King Dedede | V17: Mega Man | W17: Ganondorf | X17: Joker | Y17: Villager | Z17: Ganondorf | AA17: Piranha Plant | AB17: Luigi | AC17: Bowser Jr. | AD17: Hero | AE17: Samus | AF17: Richter | AG17: Ken | AH17: Pac Man | AI17: Terry | AJ17: Samus | AK17: Mario | AL17: Villager | AM17: Meta Knight
A18: King Dedede | B18: Snake | C18: Yoshi | D18: Bayonetta | E18: Cloud | F18: Robin | G18: Cloud | H18: Cloud | I18: Greninja | J18: Snake | K18: Incineroar | L18: Corrin | M18: Samus | N18: Ganondorf | O18: King Dedede | P18: Zero Suit Samus | Q18: Terry | R18: Roy | S18: Ganondorf | T18: Mega Man | U18: Bowser Jr. | V18: Byleth | W18: Piranha Plant | X18: Terry | Y18: Incineroar | Z18: Dark Samus | AA18: King Dedede | AB18: Ganondorf | AC18: Terry | AD18: King Dedede | AE18: Kirby | AF18: Terry | AG18: Dark Samus | AH18: Bayonetta | AI18: Lucario | AJ18: Daisy | AK18: Ness | AL18: Greninja | AM18: Zero Suit Samus
A19: Donkey Kong | B19: Jigglypuff | C19: Captain Falcon | D19: Snake | E19: Meta Knight | F19: Corrin | G19: Kirby | H19: Meta Knight | I19: Zero Suit Samus | J19: Ganondorf | K19: Pichu | L19: Banjo-Kazooie | M19: Snake | N19: Ice-Climbers | O19: Captain Falcon | P19: Kirby | Q19: Falco | R19: Bayonetta | S19: King Dedede | T19: King Dedede | U19: Samus | V19: Min Min | W19: King Dedede | X19: Captain Falcon | Y19: King Dedede | Z19: Simon | AA19: Sephiroth | AB19: Ken | AC19: Samus | AD19: Steve | AE19: King Dedede | AF19: Lucario | AG19: Mega Man | AH19: Villager | AI19: Ness | AJ19: Meta Knight | AK19: Corrin | AL19: Mii Gunner | AM19: Ganondorf
A20: Wario | B20: Joker | C20: Corrin | D20: Wolf | E20: Kirby | F20: Villager | G20: Ganondorf | H20: King Dedede | I20: Samus | J20: Olimar | K20: Fox | L20: Ganondorf | M20: Villager | N20: King Dedede | O20: Link | P20: Samus | Q20: Bayonetta | R20: Ganondorf | S20: Banjo-Kazooie | T20: Sora | U20: Pyra | V20: King Dedede | W20: Toon Link | X20: Ganondorf | Y20: Byleth | Z20: Captain Falcon | AA20: Ganondorf | AB20: Samus | AC20: King Dedede | AD20: Min Min | AE20: Ness | AF20: Ken | AG20: Samus | AH20: Mario | AI20: Joker | AJ20: Pichu | AK20: Meta Knight | AL20: Donkey Kong | AM20: Daisy
A23: 45211 | B23: 45225 | C23: 45227 | D23: 45227 | E23: 45227 | F23: 45248 | G23: 45248 | H23: 45248 | I23: 45248 | J23: 45248 | K23: 45248 | O23: 45295 | P23: 45295 | Q23: 45302 | R23: 45302 | S23: 45309 | T23: 45311 | U23: 45316 | V23: 45323 | W23: 45329 | X23: 45329 | Z23: 45337 | AA23: 45337 | AB23: 45358 | AC23: 45365 | AD23: 45372 | AE23: 45372
A24: Pit | B24: Byleth | C24: Byleth | D24: Sonic | E24: Joker | F24: Wario | G24: Terry | H24: Terry | I24: Mega Man | J24: Bayonetta | K24: Terry | O24: Samus | P24: Villager | Q24: Yoshi | R24: Mega Man | S24: Villager | T24: Ness | U24: Mario | V24: Ness | W24: Byleth | X24: Byleth | Z24: Villager | AA24: Ken | AB24: Byleth | AC24: Byleth | AD24: Villager | AE24: Lucario
A25: Villager | B25: Donkey Kong | C25: Mega Man | D25: King Dedede | E25: King Dedede | F25: Villager | G25: Mega Man | H25: Byleth | I25: Luigi | J25: Piranha Plant | K25: Bayonetta | O25: Ganondorf | P25: Ganondorf | Q25: Byleth | R25: Lucas | S25: Byleth | T25: Bayonetta | U25: Samus | V25: Byleth | W25: King K Rool | X25: Pikachu | Z25: Ness | AA25: Villager | AB25: Pit | AC25: Ganondorf | AD25: Joker | AE25: Captain Falcon
A26: Ganondorf | B26: Banjo-Kazooie | C26: Marth | D26: Byleth | E26: Byleth | F26: Samus | G26: Byleth | H26: Mr. Game & Watch | I26: Samus | J26: Terry | K26: Wario | O26: Mega Man | P26: Mewtwo | Q26: Lucas | R26: Samus | S26: Bowser Jr. | T26: Princess Peach | U26: King K Rool | V26: Young Link | W26: Donkey Kong | X26: Kazuya | Z26: King K Rool | AA26: Samus | AB26: Jigglypuff | AC26: Samus | AD26: Pikachu | AE26: Pikachu
A27: Mythra | B27: Samus | C27: Donkey Kong | D27: Joker | E27: Pyra/Mythra | F27: Incineroar | G27: King Dedede | H27: Princess Peach | I27: Jigglypuff | J27: Princess Peach | K27: King Dedede | O27: Corrin | P27: Samus | Q27: Sora | R27: Dr. Mario | S27: Shulk | T27: Piranha Plant | U27: Little Mac | V27: Samus | W27: Steve | X27: Ness | Z27: Donkey Kong | AA27: Sephiroth | AB27: Samus | AC27: Little Mac | AD27: Ness | AE27: Villager
A28: Terry | B28: Terry | C28: Samus | D28: Mega Man | E28: Samus | F28: Princess Peach | G28: Duck Hunt | H28: Wario | I28: King Dedede | J28: Sheik | K28: Mr. Game & Watch | O28: Samus | P28: Diddy Kong | Q28: Samus | R28: Byleth | S28: Mega Man | T28: Dr. Mario | U28: Mega Man | V28: R.O.B. | W28: Samus | X28: King K Rool | Z28: Byleth | AA28: Ness | AB28: King K Rool | AC28: Dr. Mario | AD28: Samus | AE28: Ice Climbers
A29: Isabelle | B29: Fox | C29: Sonic | D29: Samus | E29: Sonic | F29: Terry | G29: Lucario | H29: Greninja | I29: Kazuya | J29: Mr. Game & Watch | K29: Piranha Plant | O29: Cloud | P29: Corrin | Q29: Mario | R29: Min-Min | S29: Banjo-Kazooie | T29: Meta Knight | U29: Bayonetta | V29: Kazuya | W29: Pikachu | X29: Samus | Z29: Samus | AA29: Byleth | AB29: Villager | AC29: Pit | AD29: Lucario | AE29: Ness
A30: Samus | B30: Hero | C30: Corrin | D30: Marth | E30: Shulk | F30: Mr. Game & Watch | G30: Samus | H30: Ryu | I30: Terry | J30: Byleth | K30: Princess Peach | O30: Isabelle | P30: Ken | Q30: Mega Man | R30: Bowser | S30: King K Rool | T30: Terry | U30: Terry | V30: Ken | W30: Simon | X30: Donkey Kong | Z30: Min-Min | AA30: King K Rool | AB30: Little Mac | AC30: Kirby | AD30: Rosalina | AE30: Donkey Kong
A31: Luigi | B31: Mario | C31: King Dedede | D31: Donkey Kong | E31: Donkey Kong | F31: Zero Suit Samus | G31: Bowser | H31: Samus | I31: Pit | J31: Wario | K31: Diddy Kong | O31: Little Mac | P31: Lucas | Q31: Dr. Mario | R31: Little Mac | S31: Steve | T31: Pac Man | U31: Villager | V31: Dr. Mario | W31: Ness | X31: Simon | Z31: Diddy Kong | AA31: Bowser Jr. | AB31: Donkey Kong | AC31: Bayonetta | AD31: Donkey Kong | AE31: Samus
A33: 45386 | B33: 45386 | C33: 45387 | D33: 45387 | E33: 45393 | F33: 45393 | G33: 45399 | H33: 45399 | I33: 45407 | K33: History | R33: 45409 | S33: 45409 | T33: 45409 | U33: 45414 | V33: 45414 | W33: 45421 | X33: 45421 | Y33: 45444 | Z33: 45444 | AA33: 45449 | AB33: 45449 | AC33: 45484 | AD33: 45498 | AE33: 45505 | AF33: 45505
A34: Byleth | B34: Villager | C34: Mega Man | D34: Villager | E34: Lucario | F34: Byleth | G34: Villager | H34: Pokemon Trainer | I34: Lucario | K34: 4,7,8,2,3,6,5 | R34: Kirby | S34: Byleth | T34: Samus | U34: Pikachu | V34: Mega Man | W34: Zelda | X34: Samus | Y34: Zelda | Z34: Byleth | AA34: Mii Sword Fighter | AB34: Samus | AC34: Villager | AD34: Pichu | AE34: Ness | AF34: King Dedede
A35: Lucario | B35: Jigglypuff | C35: Villager | D35: Jigglypuff | E35: Byleth | F35: Zelda | G35: Ness | H35: Palutena | I35: Kazuya | K35: 3,6,2,7,6,4,2,1,3,2,8,7,6,1,2,3,4,8,2,6,8 | R35: Pyra/Mythra | S35: Pyra/Mythra | T35: Luigi | U35: Bowser | V35: Inkling | W35: Robin | X35: Lucario | Y35: King Dedede | Z35: Zelda | AA35: Samus | AB35: Ness | AC35: Mega Man | AD35: Pokemon Trainer | AE35: Rosalina | AF35: Samus
A36: Olimar | B36: Byleth | C36: Wii Fit Trainer | D36: Mega Man | E36: Zelda | F36: Lucario | G36: Pit | H36: Kirby | I36: Sora | K36: 6,5,4,8,7,7,5 | R36: Pikachu | S36: Pikachu | T36: Byleth | U36: Ice-Climbers | V36: Steve | W36: Ness | X36: Mii Gunner | Y36: Byleth | Z36: Ness | AA36: Ness | AB36: Lucario | AC36: Pokemon Trainer | AD36: King Dedede | AE36: Mario | AF36: Pichu
A37: Toon Link | B37: Samus | C37: Ike | D37: Robin | E37: Pac Man | F37: Pac Man | G37: Pokemon Trainer | H37: Pichu | I37: Samus | K37: 6,6,5,3,8 | R37: Samus | S37: Samus | T37: Ness | U37: Ryu | V37: Pikachu | W37: Samus | X37: King K Rool | Y37: Pokemon Trainer | Z37: King Dedede | AA37: Lucario | AB37: Corrin | AC37: Samus | AD37: Zelda | AE37: Villager | AF37: Villager
A38: Mewtwo | B38: Banjo-Kazooie | C38: Byleth | D38: Palutena | E38: King K Rool | F38: Roy | G38: Bowser | H38: Hero | I38: Pikachu | K38: 1,2,2,6,3,8,2,4,1,1,1,1,1,3,3,3,2,7,5,1,5,2,2,5,2,2,1,1,5,6,1,1,1,3,5,2,1 | R38: Donkey Kong | S38: Cloud | T38: Sephiroth | U38: Samus | V38: Mii Gunner | W38: Pokemon Trainer | X38: Pokemon Trainer | Y38: Ness | Z38: Samus | AA38: Corrin | AB38: Isabelle | AC38: Corrin | AD38: Corrin | AE38: Samus | AF38: Ness
A39: Samus | B39: Lucario | C39: Pyra | D39: Pyra | E39: Ness | F39: Terry | G39: Lucario | H39: Villager | I39: Diddy Kong | K39: 1,1,2,5,1,6,6,8,4,5,8,1,4,2,7,2,8,2,5,7,2,4,3,1,7,2,4,7,8,6,2 | R39: Mega Man | S39: Luigi | T39: Mega Man | U39: Byleth | V39: Kirby | W39: Lucario | X39: Rosalina | Y39: Samus | Z39: Sheik | AA39: Ganondorf | AB39: Ganondorf | AC39: Pit | AD39: Samus | AE39: King Dedede | AF39: Meta Knight
A40: Bowser | B40: R.O.B. | C40: Cloud | D40: Wii Fit Trainer | E40: R.O.B. | F40: Piranha Plant | G40: Palutena | H40: Ness | I40: King Dedede | K40: 1 | R40: Byleth | S40: Mega Man | T40: Pichu | U40: Mii Gunner | V40: Samus | W40: Rosalina | X40: Ness | Y40: Bayonetta | Z40: Pikachu | AA40: Simon | AB40: Mii Sword Fighter | AC40: King Dedede | AD40: Mega Man | AE40: Meta Knight | AF40: Donkey Kong
A41: Marth | B41: Lucina | C41: Villager | D41: Falco | E41: Shulk | F41: Ness | G41: Duck Hunt | H41: Isabelle | I41: Ike | K41: 1,5,8,8,1,2,6,6,6,2,4,6,7 | R41: Yoshi | S41: Samus | T41: Pyra/Mythra | U41: Inkling | V41: Ryu | W41: Richter/Simon | X41: Robin | Y41: King K Rool | Z41: Sonic | AA41: Roy | AB41: Corrin | AC41: Lucario | AD41: R.O.B. | AE41: Pichu | AF41: Diddy Kong
K42: 4,2,3,2,2,3,1,3,1,2,5,7,8,3,4,8,4,7,4,5,6,2,2,2,8,3,7,6,4,7,7,1,7,4,6
K43: 2,6,8
K44: 1,8,8,5,8,6 | R44: 45540 | S44: 45542 | T44: 45542 | U44: 45542 | V44: 45542 | W44: 45542 | X44: 45542 | Y44: 45547 | Z44: 45547 | AA44: 45549
K45: 7,4,7,7,4,5,8,4,2,6,1,6,5,6,1,6,7,7,6,5,7,5,7,1,3,8,2,4,8,8,3,7,4,8,8,7 | R45: Link | S45: Ganondorf | T45: Samus | U45: Pichu | V45: Kirby | W45: Lucas | X45: Pikachu | Y45: Villager | Z45: Villager | AA45: Falco
...

Sheet Sheet4
A1: Character | B1: Top 8's | C1: Trophies | D1: Avg Position | G1: Character | H1: Top 8's | I1: Trophies | J1: Avg Position | M1: Character | N1: Top 8's | O1: Trophies | P1: Avg Position | S1: Character | T1: Top 8's | U1: Trophies | V1: Avg Position | Y1: Character | Z1: Top 8's | AA1: Trophies | AB1: Avg Position | AE1: Character | AF1: Top 8's | AG1: Trophies | AH1: Avg Position
A2: Corrin | B2: 9 | C2: 2 | D2: 2.33 | E2: ▲1 | G2: Kirby | H2: 6 | I2: 1 | J2: 2.67 | K2: ▲1 | M2: Broken Kirby | N2: 9 | O2: 🏆🏆🏆 | P2: 2.89 | S2: Kirby | T2: 10 | U2: 🏆🏆🏆 | V2: 3.2 | Y2: Kirby | Z2: 10 | AA2: 🏆🏆🏆 | AB2: 3.2 | AE2: Falco | AF2: 3 | AG2: 0 | AH2: 3.33 | AI2: New God Tier
A3: Kirby | B3: 6 | C3: 1 | D3: 2.67 | E3: ▼1 | G3: Corrin | H3: 13 | I3: 2 | J3: 3.31 | K3: ▼1 | M3: Mega Man | N3: 5 | O3: 🏆 | P3: 3.6 | Q3: ▲1 | S3: Mega Man | T3: 5 | U3: 🏆 | V3: 3.6 | Y3: Mega Man | Z3: 5 | AA3: 🏆 | AB3: 3.6 | AE3: Kirby | AF3: 12 | AG3: 3 | AH3: 3.58 | AI3: ▼1
A4: Mega Man | B4: 5 | C4: 1 | D4: 3.6 | E4: ▲1 | G4: Mega Man | H4: 5 | I4: 1 | J4: 3.6 | M4: Corrin | N4: 17 | O4: 🏆🏆 | P4: 3.65 | Q4: ▼1 | S4: Corrin | T4: 18 | U4: 🏆🏆 | V4: 3.83 | Y4: Corrin | Z4: 19 | AA4: 🏆🏆 | AB4: 3.84 | AE4: Mega Man | AF4: 5 | AG4: 1 | AH4: 3.6 | AI4: ▼1
A5: King Dedede | B5: 10 | C5: 3 | D5: 3.7 | E5: ▼1 | G5: Samus | H5: 4 | I5: 0 | J5: 3.75 | K5: ▲2 | M5: Mario | N5: 3 | O5: 0 | P5: 3.67 | Q5: New | S5: Captain Falcon | T5: 13 | U5: 🏆🏆🏆🏆 | V5: 4 | W5: ▲1 | Y5: Captain Falcon | Z5: 13 | AA5: 🏆🏆🏆🏆 | AB5: 4 | AE5: Corrin | AF5: 23 | AG5: 2 | AH5: 3.83 | AI5: ▼1
A6: Captain Falcon | B6: 8 | C6: 3 | D6: 3.75 | G6: Jigglypuff | H6: 4 | I6: 0 | J6: 3.75 | K6: ▲2 | M6: Captain Falcon | N6: 10 | O6: 🏆🏆🏆 | P6: 3.9 | Q6: ▲1 | S6: Palutena | T6: 3 | U6: 0 | V6: 4 | W6: ▲1 | Y6: King Dedede | Z6: 16 | AA6: 🏆🏆🏆 | AB6: 4 | AC6: ▲1 | AE6: Captain Falcon | AF6: 14 | AG6: 4 | AH6: 3.86 | AI6: ▼1
A7: Samus | B7: 4 | C7: 0 | D7: 3.75 | E7: ▲2 | G7: Captain Falcon | H7: 10 | I7: 3 | J7: 3.9 | K7: ▼1 | M7: Palutena | N7: 3 | O7: 0 | P7: 4 | Q7: New | S7: King Dedede | T7: 15 | U7: 🏆🏆🏆 | V7: 4.07 | W7: ▲1 | Y7: Palutena | Z7: 3 | AA7: 0 | AB7: 4 | AC7: ▼1 | AE7: King Dedede | AF7: 16 | AG7: 3 | AH7: 4 | AI7: ▼1
A8: Jigglypuff | B8: 4 | C8: 0 | D8: 3.75 | E8: New | G8: King Dedede | H8: 12 | I8: 3 | J8: 4 | K8: ▼3 | M8: Mid Dedede | N8: 14 | O8: 🏆🏆🏆 | P8: 4.07 | S8: Meta Knight | T8: 8 | U8: 0 | V8: 4.13 | W8: ▲1 | Y8: Meta Knight | Z8: 8 | AA8: 0 | AB8: 4.13 | AE8: Palutena | AF8: 3 | AG8: 0 | AH8: 4 | AI8: ▼1
A9: Sonic | B9: 3 | C9: 1 | D9: 4 | E9: ▼2 | G9: Sonic | H9: 3 | I9: 1 | J9: 4 | M9: Meta Knight | N9: 8 | O9: 0 | P9: 4.13 | Q9: ▲1 | S9: Sonic | T9: 4 | U9: 🏆 | V9: 4.25 | W9: ▲1 | Y9: Mario | Z9: 5 | AA9: 0 | AB9: 4.2 | AC9: ▲5 | AE9: Ness | AF9: 5 | AG9: 1 | AH9: 4 | AI9: New Mid Tier
A10: Meta Knight | B10: 8 | C10: 0 | D10: 4.13 | E10: ▼2 | G10: Meta Knight | H10: 8 | I10: 0 | J10: 4.13 | M10: Sonic | N10: 4 | O10: 🏆 | P10: 4.25 | Q10: ▼1 | S10: Mewtwo | T10: 3 | U10: 0 | V10: 4.33 | W10: ▲1 | Y10: Sonic | Z10: 4 | AA10: 🏆 | AB10: 4.25 | AC10: ▼1 | AE10: Meta Knight | AF10: 10 | AG10: 0 | AH10: 4.1 | AI10: ▼2
A11: Ganondorf | B11: 4 | C11: 1 | D11: 5 | E11: New | G11: Donkey Kong | H11: 16 | I11: 2 | J11: 4.94 | K11: ▲1 | M11: Mewtwo | N11: 3 | O11: 0 | P11: 4.33 | Q11: New | S11: Ridley | T11: 4 | U11: 🏆 | V11: 4.5 | W11: ▲1 | Y11: Mewtwo | Z11: 3 | AA11: 0 | AB11: 4.33 | AC11: ▼1 | AE11: R.O.B. | AF11: 5 | AG11: 0 | AH11: 4.2 | AI11: New Mid Tier
A12: Donkey Kong | B12: 14 | C12: 1 | D12: 5.14 | E12: ▼2 | G12: Ganondorf | H12: 4 | I12: 1 | J12: 5 | K12: ▼1 | M12: Ridley | N12: 4 | O12: 🏆 | P12: 4.5 | Q12: ▲3 | S12: Samus | T12: 5 | U12: 0 | V12: 4.6 | W12: ▲1 | Y12: Samus | Z12: 5 | AA12: 0 | AB12: 4.6 | AE12: Sonic | AF12: 4 | AG12: 1 | AH12: 4.25 | AI12: ▼2
A13: Cloud | B13: 4 | C13: 1 | D13: 5.5 | E13: New | G13: King K Rool | H13: 8 | I13: 1 | J13: 5.38 | K13: ▲3 | M13: Samus | N13: 5 | O13: 0 | P13: 4.6 | Q13: ▼8💀 | S13: Cloud | T13: 5 | U13: 🏆🏆 | V13: 4.6 | W13: ▲1 | Y13: Cloud | Z13: 5 | AA13: 🏆🏆 | AB13: 4.6 | AE13: Villager | AF13: 4 | AG13: 1 | AH13: 4.25 | AI13: ▲7
A14: Ridley | B14: 3 | C14: 0 | D14: 5.67 | E14: ▼3 | G14: Cloud | H14: 4 | I14: 1 | J14: 5.5 | K14: ▼1 | M14: Cloud | N14: 5 | O14: 🏆🏆 | P14: 4.6 | S14: Mario | T14: 4 | U14: 0 | V14: 4.75 | W14: ▼9💀 | Y14: Ridley | Z14: 5 | AA14: 🏆 | AB14: 4.8 | AC14: ▼3 | AE14: Mewtwo | AF14: 3 | AG14: 0 | AH14: 4.33 | AI14: ▼3
A15: Yoshi | B15: 5 | C15: 0 | D15: 6 | E15: ▼3 | G15: Ridley | H15: 3 | I15: 0 | J15: 5.67 | K15: ▼1 | M15: Yoshi | N15: 10 | O15: 🏆 | P15: 4.8 | Q15: ▲1 | S15: Yoshi | T15: 10 | U15: 🏆 | V15: 4.8 | Y15: Yoshi | Z15: 10 | AA15: 🏆 | AB15: 4.8 | AE15: Luigi | AF15: 3 | AG15: 0 | AH15: 4.33 | AI15: New Mid Tier
A16: King K Rool | B16: 6 | C16: 0 | D16: 6 | E16: ▼2 | G16: Yoshi | H16: 5 | I16: 0 | J16: 6 | K16: ▼1 | M16: Trashdorf | N16: 7 | O16: 🏆 | P16: 5.14 | Q16: ▼4 | S16: Ganondorf | T16: 8 | U16: 🏆 | V16: 5.13 | Y16: Rosalina | Z16: 3 | AA16: 0 | AB16: 5 | AC16: New Trash | AE16: Mario | AF16: 7 | AG16: 0 | AH16: 4.57 | AI16: ▼7💀
A17: Pikachu | B17: 4 | C17: 0 | D17: 6.25 | E17: ▼4 | G17: Pikachu | H17: 4 | I17: 0 | J17: 6.25 | M17: Jigglytrash | N17: 6 | O17: 0 | P17: 5.17 | Q17: ▼11💀 | S17: Jigglypuff | T17: 6 | U17: 0 | V17: 5.17 | Y17: Ganondorf | Z17: 8 | AA17: 🏆 | AB17: 5.13 | AC17: ▼1 | AE17: Samus | AF17: 5 | AG17: 0 | AH17: 4.6 | AI17: ▼5
M18: Trash Kong | N18: 20 | O18: 🏆🏆 | P18: 5.2 | Q18: ▼7💀 | S18: Donkey Kong | T18: 22 | U18: 🏆🏆 | V18: 5.27 | Y18: Jigglypuff | Z18: 6 | AA18: 0 | AB18: 5.17 | AC18: ▼1 | AE18: Cloud | AF18: 5 | AG18: 2 | AH18: 4.6 | AI18: ▼5
M19: King K Trash | N19: 8 | O19: 🏆 | P19: 5.38 | Q19: ▼6 | S19: Villager | T19: 3 | U19: 0 | V19: 5.33 | W19: New Trash | Y19: Donkey Kong | Z19: 22 | AA19: 🏆🏆 | AB19: 5.27 | AC19: ▼1 | AE19: Yoshi | AF19: 10 | AG19: 1 | AH19: 4.8 | AI19: ▼4
M20: Trashchu | N20: 6 | O20: 0 | P20: 5.67 | Q20: ▼3 | S20: King K Rool | T20: 8 | U20: 🏆 | V20: 5.38 | W20: ▼1 | Y20: Villager | Z20: 3 | AA20: 0 | AB20: 5.33 | AC20: ▼1 | AE20: Rosatrash | AF20: 3 | AG20: 0 | AH20: 5 | AI20: ▼4
S21: Pikachu | T21: 6 | U21: 0 | V21: 5.67 | W21: ▼1 | Y21: King K Rool | Z21: 8 | AA21: 🏆 | AB21: 5.38 | AC21: ▼1 | AE21: Trashdorf | AF21: 8 | AG21: 1 | AH21: 5.13 | AI21: ▼4
S22: Fox | T22: 3 | U22: 0 | V22: 7.33 | W22: New Trash | Y22: Pikachu | Z22: 6 | AA22: 0 | AB22: 5.67 | AC22: ▼1 | AE22: Jigglytrash | AF22: 6 | AG22: 0 | AH22: 5.17 | AI22: ▼4
Y23: Fox | Z23: 3 | AA23: 0 | AB23: 7.33 | AC23: ▼1 | AE23: Trashley | AF23: 6 | AG23: 1 | AH23: 5.17 | AI23: ▼9💀
AE24: Trash Kong | AF24: 22 | AG24: 2 | AH24: 5.27 | AI24: ▼5
AE25: King K Trash | AF25: 8 | AG25: 1 | AH25: 5.38 | AI25: ▼4
AE26: Trashchu | AF26: 6 | AG26: 0 | AH26: 5.67 | AI26: ▼4
AE27: Trashiest of the Trash | AF27: 4 | AG27: 0 | AH27: 7.5 | AI27: ▼4
A31: Character | B31: Top 8's | C31: Trophies | D31: Avg Position | G31: Character | H31: Top 8's | I31: Trophies | J31: Avg Position | M31: Character | N31: Top 8's | O31: Trophies | P31: Avg Position | Q31: Trophy Rate | S31: Character | T31: Top 8's | U31: Trophies | V31: Avg Position | W31: Trophy Rate | Z31: Character | AA31: Top 8's | AB31: Trophies | AC31: Avg Position | AD31: Trophy Rate | AF31: Character | AG31: Top 8's | AH31: Trophies | AI31: Avg Position | AJ31: Trophy Rate
A32: Falco | B32: 4 | C32: 0 | D32: 3 | G32: Falco | H32: 4 | I32: 0 | J32: 3 | M32: Falco | N32: 4 | O32: 0 | P32: 3 | Q32: 0 | S32: Falco | T32: 4 | U32: 0 | V32: 3 | W32: 0 | Z32: Falco | AA32: 4 | AB32: 0 | AC32: 3 | AD32: 0 | AF32: Falco | AG32: 4 | AH32: 0 | AI32: 3 | AJ32: 0
A33: Incineroar | B33: 3 | C33: 1 | D33: 3.33 | E33: New God Tier | G33: Incineroar | H33: 3 | I33: 1 | J33: 3.33 | M33: Link | N33: 3 | O33: 1 | P33: 3 | Q33: 0.33 | R33: New | S33: Link | T33: 3 | U33: 1 | V33: 3 | W33: 0.33 | Z33: Link | AA33: 3 | AB33: 1 | AC33: 3 | AD33: 0.33 | AF33: Link | AG33: 3 | AH33: 1 | AI33: 3 | AJ33: 0.33
A34: Kirby | B34: 12 | C34: 3 | D34: 3.58 | E34: ▼1 | G34: Kirby | H34: 12 | I34: 3 | J34: 3.58 | M34: Incineroar | N34: 3 | O34: 1 | P34: 3.33 | Q34: 0.33 | R34: ▼1 | S34: Incineroar | T34: 3 | U34: 1 | V34: 3.33 | W34: 0.33 | Z34: Incineroar | AA34: 3 | AB34: 1 | AC34: 3.33 | AD34: 0.33 | AF34: Incineroar | AG34: 3 | AH34: 1 | AI34: 3.33 | AJ34: 0.33
A35: Mega Man | B35: 5 | C35: 1 | D35: 3.6 | E35: ▼1 | G35: Mega Man | H35: 5 | I35: 1 | J35: 3.6 | M35: Kirby | N35: 12 | O35: 3 | P35: 3.58 | Q35: 0.25 | R35: ▼1 | S35: King Dedede | T35: 24 | U35: 7 | V35: 3.5 | W35: 0.29 | X35: ▲2 | Z35: King Dedede | AA35: 24 | AB35: 7 | AC35: 3.5 | AD35: 0.29 | AF35: King Dedede | AG35: 26 | AH35: 8 | AI35: 3.35 | AJ35: 0.31
A36: King Dedede | B36: 17 | C36: 4 | D36: 3.82 | E36: ▲1 | G36: King Dedede | H36: 19 | I36: 5 | J36: 3.63 | M36: Mega Man | N36: 5 | O36: 1 | P36: 3.6 | Q36: 0.2 | R36: ▼1 | S36: Kirby | T36: 13 | U36: 3 | V36: 3.54 | W36: 0.23 | X36: ▼1 | Z36: Kirby | AA36: 13 | AB36: 3 | AC36: 3.54 | AD36: 0.23 | AF36: Mega Man | AG36: 5 | AH36: 1 | AI36: 3.6 | AJ36: 0.2 | AK36: ▲1
A37: Corrin | B37: 23 | C37: 2 | D37: 3.83 | E37: ▼2 | G37: Corrin | H37: 23 | I37: 2 | J37: 3.83 | M37: King Dedede | N37: 23 | O37: 6 | P37: 3.61 | Q37: 0.26 | R37: ▼1 | S37: Mega Man | T37: 5 | U37: 1 | V37: 3.6 | W37: 0.2 | X37: ▼1 | Z37: Mega Man | AA37: 5 | AB37: 1 | AC37: 3.6 | AD37: 0.2 | AF37: Samus | AG37: 9 | AH37: 1 | AI37: 3.78 | AJ37: 0.11 | AK37: ▲1
A38: Palutena | B38: 3 | C38: 0 | D38: 4 | G38: Samus | H38: 8 | I38: 1 | J38: 3.88 | K38: ▲10 | M38: Corrin | N38: 23 | O38: 2 | P38: 3.83 | Q38: 0.09 | R38: ▼1 | S38: Corrin | T38: 24 | U38: 2 | V38: 3.75 | W38: 0.08 | Z38: Samus | AA38: 9 | AB38: 1 | AC38: 3.78 | AD38: 0.11 | AE38: ▲1 | AF38: Kirby | AG38: 14 | AH38: 3 | AI38: 3.86 | AJ38: 0.21 | AK38: ▼2
A39: Captain Falcon | B39: 15 | C39: 4 | D39: 4.07 | E39: ▼3 | G39: Palutena | H39: 3 | I39: 0 | J39: 4 | K39: ▼1 | M39: Samus | N39: 8 | O39: 1 | P39: 3.88 | Q39: 0.13 | R39: ▼1 | S39: Samus | T39: 8 | U39: 1 | V39: 3.88 | W39: 0.13 | Z39: Corrin | AA39: 25 | AB39: 2 | AC39: 3.92 | AD39: 0.08 | AE39: ▼1 | AF39: Corrin | AG39: 26 | AH39: 2 | AI39: 3.88 | AJ39: 0.08
A40: Meta Knight | B40: 10 | C40: 0 | D40: 4.1 | G40: Captain Falcon | H40: 15 | I40: 4 | J40: 4.07 | K40: ▼1 | M40: Palutena | N40: 3 | O40: 0 | P40: 4 | Q40: 0 | R40: ▼1 | S40: Palutena | T40: 3 | U40: 0 | V40: 4 | W40: 0 | Z40: Palutena | AA40: 3 | AB40: 0 | AC40: 4 | AD40: 0 | AF40: Palutena | AG40: 3 | AH40: 0 | AI40: 4 | AJ40: 0
A41: Sonic | B41: 4 | C41: 1 | D41: 4.25 | E41: ▲1 | G41: Meta Knight | H41: 10 | I41: 0 | J41: 4.1 | K41: ▼1 | M41: Inkling | N41: 3 | O41: 0 | P41: 4 | Q41: 0 | R41: New | S41: Inkling | T41: 3 | U41: 0 | V41: 4 | W41: 0 | Z41: Inkling | AA41: 3 | AB41: 0 | AC41: 4 | AD41: 0 | AF41: Inkling | AG41: 3 | AH41: 0 | AI41: 4 | AJ41: 0
A42: Villager | B42: 4 | C42: 1 | D42: 4.25 | E42: ▲1 | G42: Sonic | H42: 4 | I42: 1 | J42: 4.25 | K42: ▼1 | M42: Wario | N42: 3 | O42: 1 | P42: 4 | Q42: 0.33 | R42: New | S42: Wario | T42: 3 | U42: 1 | V42: 4 | W42: 0.33 | Z42: Wario | AA42: 3 | AB42: 1 | AC42: 4 | AD42: 0.33 | AF42: Wario | AG42: 3 | AH42: 1 | AI42: 4 | AJ42: 0.33
A43: Mewtwo | B43: 3 | C43: 0 | D43: 4.33 | E43: ▲1 | G43: Villager | H43: 4 | I43: 1 | J43: 4.25 | K43: ▼1 | M43: Captain Falcon | N43: 18 | O43: 4 | P43: 4.06 | Q43: 0.22 | R43: ▼3 | S43: Meta Knight | T43: 10 | U43: 0 | V43: 4.1 | W43: 0 | X43: ▲1 | Z43: Cloud | AA43: 6 | AB43: 2 | AC43: 4.17 | AD43: 0.33 | AE43: ▲9 | AF43: R.O.B. | AG43: 8 | AH43: 0 | AI43: 4.13 | AJ43: 0 | AK43: ▲5
...

Sheet Prep 2.0
A1: 45512 | B1: 45512 | C1: 45512 | D1: 45519 | E1: 45519 | F1: 45526 | G1: 45526 | H1: 45528 | I1: 45531 | J1: 45531 | K1: 45533 | L1: 45533
A2: Lucario | B2: Pokemon Trainer | C2: King Dedede | D2: Lucario | E2: King Dedede | F2: Samus | G2: Ness | H2: Villager | I2: Lucario | J2: Jigglypuff | K2: Snake | L2: Zelda
A3: Dark Pit | B3: Wolf | C3: Zelda | D3: Zelda | E3: Lucario | F3: Ike | G3: Samus | H3: Sonic | I3: Ganondorf | J3: Pac Man | K3: Samus | L3: Falco
A4: Mega Man | B4: Lucario | C4: Pokemon Trainer | D4: Ness | E4: Ness | F4: Ganondorf | G4: Bayonetta | H4: Lucario | I4: Sheik | J4: Olimar | K4: Wario | L4: Pikachu
A5: Pokemon Trainer | B5: Ganondorf | C5: Ike | D5: Samus | E5: Ike | F5: Bayonetta | G5: Ganondorf | H5: Zelda | I5: Ike | J5: Falco | K5: Bowser | L5: Diddy Kong
A6: Zelda | B6: Dark Pit | C6: Samus | D6: King Dedede | E6: Ganondorf | F6: Meta Knight | G6: Meta Knight | H6: Ganondorf | I6: Villager | J6: Bayonetta | K6: Ganondorf | L6: Ganondorf
A7: Ganondorf | B7: Samus | C7: Lucario | D7: Corrin | E7: Samus | F7: Lucario | G7: Ike | H7: Incineroar | I7: Pikachu | J7: Sheik | K7: Duck Hunt | L7: Samus
A8: Wolf | B8: Mega Man | C8: Ganondorf | D8: Villager | E8: Zelda | F8: Diddy Kong | G8: Lucario | H8: King Dedede | I8: Samus | J8: Shulk | K8: Zelda | L8: R.O.B.
A9: Samus | B9: Zelda | C9: Duck Hunt | D9: Ganondorf | E9: Villager | F9: Ness | G9: Diddy Kong | H9: Ness | I9: Zelda | J9: Little Mac | K9: Diddy Kong | L9: Pokemon Trainer
A12: Character | B12: Top 8's | C12: Trophies | D12: Avg Position | E12: Total | F12: STD | I12: Character | J12: Top 8's | K12: Trophies | L12: Avg Position | M12: Trophy Rate | N12: STD
A13: Banjo-Kazooie | B13: 7 | C13: 0 | D13: =E13/B13 -> 5 | E13: 35 | F13: 2.3664319 | I13: Banjo-Kazooie | J13: 7 | K13: 0 | L13: 5 | M13: =K13/J13 -> 0 | N13: 2.3664319
A14: Bayonetta | B14: 25 | C14: 2 | D14: =E14/B14 -> 4.4 | E14: 110 | F14: 2.3273733 | I14: Bayonetta | J14: 25 | K14: 2 | L14: 4.4 | M14: =K14/J14 -> 0.08 | N14: 2.3273733
A15: Bowser | B15: 9 | C15: 0 | D15: =E15/B15 -> 5.3333333 | E15: 48 | F15: 1.8708287 | I15: Bowser | J15: 9 | K15: 0 | L15: 5.33 | M15: =K15/J15 -> 0 | N15: 1.8708287
A16: Bowser Jr. | B16: 5 | C16: 0 | D16: =E16/B16 -> 5.6 | E16: 28 | F16: 1.8165902 | I16: Bowser Jr. | J16: 5 | K16: 0 | L16: 5.6 | M16: =K16/J16 -> 0 | N16: 1.8165902
A17: Byleth | B17: 43 | C17: 15 | D17: =E17/B17 -> 2.8604651 | E17: 123 | F17: 2.0304984 | I17: Byleth | J17: 43 | K17: 15 | L17: 2.86 | M17: =K17/J17 -> 0.34883721 | N17: 2.0304984
A18: Captain Falcon | B18: 31 | C18: 5 | D18: =E18/B18 -> 4.2258065 | E18: 131 | F18: 2.4994623 | I18: Captain Falcon | J18: 31 | K18: 5 | L18: 4.23 | M18: =K18/J18 -> 0.16129032 | N18: 2.4994623
A19: Cloud | B19: 14 | C19: 2 | D19: =E19/B19 -> 4.7857143 | E19: 67 | F19: 2.4235566 | I19: Cloud | J19: 14 | K19: 2 | L19: 4.79 | M19: =K19/J19 -> 0.14285714 | N19: 2.4235566
A20: Corrin | B20: 41 | C20: 3 | D20: =E20/B20 -> 4.4634146 | E20: 183 | F20: 2.1805683 | I20: Corrin | J20: 41 | K20: 3 | L20: 4.46 | M20: =K20/J20 -> 0.073170732 | N20: 2.1805683
A21: Diddy Kong | B21: 11 | C21: 1 | D21: =E21/B21 -> 6.4545455 | E21: 71 | F21: 2.296242 | I21: Diddy Kong | J21: 11 | K21: 1 | L21: 6.45 | M21: =K21/J21 -> 0.090909091 | N21: 2.296242
A22: Donkey Kong | B22: 38 | C22: 3 | D22: =E22/B22 -> 5.4210526 | E22: 206 | F22: 2.1514493 | I22: Donkey Kong | J22: 38 | K22: 3 | L22: 5.42 | M22: =K22/J22 -> 0.078947368 | N22: 2.1514493
A23: Dr. Mario | B23: 8 | C23: 1 | D23: =E23/B23 -> 5.5 | E23: 44 | F23: 2.3299295 | I23: Duck Hunt | J23: 6 | K23: 0 | L23: 5.67 | M23: =K23/J23 -> 0 | N23: 2.3299295
A24: Duck Hunt | B24: 6 | C24: 0 | D24: =E24/B24 -> 5.6666667 | E24: 34 | F24: 2.0655911 | I24: Dr. Mario | J24: 8 | K24: 1 | L24: 5.5 | M24: =K24/J24 -> 0.125 | N24: 2.0655911
... A51: Mewtwo | B51: 5 | C51: 0 | D51: =E51/B51 -> 4.2 | E51: 21 | F51: 1.3038405 | I51: Mewtwo | J51: 5 | K51: 0 | L51: 4.2 | M51: =K51/J51 -> 0 | N51: 1.3038405
A52: Mii Brawler | B52: 1 | C52: 0 | D52: =E52/B52 -> 2 | E52: 2 | I52: Mii Gunner | J52: 5 | K52: 0 | L52: 5 | M52: =K52/J52 -> 0 | N52: 2
A53: Mii Gunner | B53: 5 | C53: 0 | D53: =E53/B53 -> 5 | E53: 25 | F53: 2 | I53: Mii Sword Fighter | J53: 5 | K53: 1 | L53: 4 | M53: =K53/J53 -> 0.2 | N53: 3.2403703
A54: Mii Swordfighter | B54: 5 | C54: 1 | D54: =E54/B54 -> 4 | E54: 20 | F54: 3.2403703 | I54: Mr. Game & Watch | J54: 7 | K54: 0 | L54: 4.57 | M54: =K54/J54 -> 0 | N54: 1.7182494
A55: Min Min | B55: 4 | C55: 0 | D55: =E55/B55 -> 7 | E55: 28 | F55: 0.81649658 | I55: Ness | J55: 41 | K55: 5 | L55: 4.41 | M55: =K55/J55 -> 0.12195122 | N55: 2.2690924
A56: Mr. Game & Watch | B56: 7 | C56: 0 | D56: =E56/B56 -> 4.5714286 | E56: 32 | F56: 1.7182494 | I56: Olimar | J56: 7 | K56: 0 | L56: 4.71 | M56: =K56/J56 -> 0 | N56: 1.7043362
A57: Ness | B57: 41 | C57: 5 | D57: =E57/B57 -> 4.4146341 | E57: 181 | F57: 2.2690924 | I57: Pac Man | J57: 7 | K57: 0 | L57: 4.71 | M57: =K57/J57 -> 0 | N57: 1.8898224
A58: Olimar | B58: 7 | C58: 0 | D58: =E58/B58 -> 4.7142857 | E58: 33 | F58: 1.7043362 | I58: Palutena | J58: 6 | K58: 0 | L58: 4.33 | M58: =K58/J58 -> 0 | N58: 2.3380904
A59: Pac Man | B59: 7 | C59: 0 | D59: =E59/B59 -> 4.7142857 | E59: 33 | F59: 1.8898224 | I59: Pichu | J59: 11 | K59: 2 | L59: 4.82 | M59: =K59/J59 -> 0.18181818 | N59: 2.5226249
A60: Palutena | B60: 6 | C60: 0 | D60: =E60/B60 -> 4.3333333 | E60: 26 | F60: 2.3380904 | I60: Pikachu | J60: 20 | K60: 1 | L60: 4.4 | M60: =K60/J60 -> 0.05 | N60: 2.0875571
A61: Pichu | B61: 11 | C61: 2 | D61: =E61/B61 -> 4.8181818 | E61: 53 | F61: 2.5226249 | I61: Piranha Plant | J61: 8 | K61: 0 | L61: 4.25 | M61: =K61/J61 -> 0 | N61: 2.0528726
A62: Pikachu | B62: 20 | C62: 1 | D62: =E62/B62 -> 4.4 | E62: 88 | F62: 2.0875571 | I62: Pit | J62: 9 | K62: 1 | L62: 3.89 | M62: =K62/J62 -> 0.11111111 | N62: 2.4209732
A63: Piranha Plant | B63: 8 | C63: 0 | D63: =E63/B63 -> 4.25 | E63: 34 | F63: 2.0528726 | I63: Pokemon Trainer | J63: 14 | K63: 2 | L63: 3.86 | M63: =K63/J63 -> 0.14285714 | N63: 1.9944979
A64: Pit | B64: 9 | C64: 1 | D64: =E64/B64 -> 3.8888889 | E64: 35 | F64: 2.4209732 | I64: Princess Peach | J64: 13 | K64: 0 | L64: 4.54 | M64: =K64/J64 -> 0 | N64: 1.9414507
... A89: Yoshi | B89: 14 | C89: 2 | D89: =E89/B89 -> 4.6428571 | E89: 65 | F89: 2.3731557 | I89: Zero Suit Samus | J89: 6 | K89: 0 | L89: 5.5 | M89: =K89/J89 -> 0 | N89: 2.1679483
A90: Young Link | B90: 5 | C90: 1 | D90: =E90/B90 -> 4.8 | E90: 24 | F90: 2.7748874
A91: Zelda | B91: 19 | C91: 4 | D91: =E91/B91 -> 3.8421053 | E91: 73 | F91: 2.587645
A92: Zero Suit Samus | B92: 6 | C92: 0 | D92: =E92/B92 -> 5.5 | E92: 33 | F92: 2.1679483
...

Sheet 2.0
A1: Character | B1: Top 8's | C1: Trophies | D1: Avg Position | E1: Trophy Rate | F1: STD | H1: Character | I1: Top 8's | J1: Trophies | K1: Avg Position | L1: Trophy Rate | M1: STD | P1: Character | Q1: Top 8's | R1: Trophies | S1: Avg Position | T1: Trophy Rate | V1: Character | W1: Top 8's | X1: Change in Top 8's | Y1: Trophies | Z1: Change in Trophies | AA1: Avg Position | AB1: Change in Avg Position
A2: Byleth | B2: 43 | C2: 15 | D2: 2.86 | E2: 0.35 | F2: 2.4994623 | H2: Byleth | I2: 43 | J2: 15 | K2: 2.86 | L2: =J2/I2 -> 0.34883721 | M2: 2.0304984 | P2: Banjo-Kazooie | Q2: 5 | R2: 0 | S2: 4.8 | T2: 0 | V2: Banjo-Kazooie | W2: 7 | X2: =W2-Q2 -> 2 | Y2: 0 | Z2: =Y2-R2 -> 0 | AA2: 5 | AB2: =AA2-S2 -> 0.2
A3: Lucario | B3: 29 | C3: 7 | D3: 3.45 | E3: 0.24 | F3: 2.1884181 | G3: ▲4 | H3: Kazuya | I3: 6 | J3: 1 | K3: 3.5 | L3: =J3/I3 -> 0.16666667 | M3: 2.0736441 | N3: ▲1 | P3: Bayonetta | Q3: 18 | R3: 2 | S3: 4.17 | T3: 0.11 | V3: Bayonetta | W3: 25 | X3: =W3-Q3 -> 7 | Y3: 2 | Z3: =Y3-R3 -> 0 | AA3: 4.4 | AB3: =AA3-S3 -> 0.23
A4: Kazuya | B4: 6 | C4: 1 | D4: 3.5 | E4: 0.17 | F4: 2.0736441 | H4: Lucario | I4: 33 | J4: 8 | K4: 3.55 | L4: =J4/I4 -> 0.24242424 | M4: 2.2233267 | N4: ▼1 | P4: Bowser | Q4: 4 | R4: 0 | S4: 5.75 | T4: 0 | V4: Bowser | W4: 9 | X4: =W4-Q4 -> 5 | Y4: 0 | Z4: =Y4-R4 -> 0 | AA4: 5.33 | AB4: =AA4-S4 -> -0.42
A5: Zelda | B5: 15 | C5: 3 | D5: 3.53 | E5: 0.2 | F5: 2.399252 | G5: ▼2 | H5: Mega Man | I5: 36 | J5: 6 | K5: 3.67 | L5: =J5/I5 -> 0.16666667 | M5: 2.1646511 | N5: ▲2 | P5: Bowser Jr. | Q5: 3 | R5: 0 | S5: 5.67 | T5: 0 | V5: Bowser Jr. | W5: 5 | X5: =W5-Q5 -> 2 | Y5: 0 | Z5: =Y5-R5 -> 0 | AA5: 5.6 | AB5: =AA5-S5 -> -0.07
A6: Pokemon Trainer | B6: 13 | C6: 2 | D6: 3.54 | E6: 0.15 | F6: 1.6641006 | H6: Villager | I6: 41 | J6: 14 | K6: 3.68 | L6: =J6/I6 -> 0.34146341 | M6: 2.6214407 | N6: ▲2 | P6: Byleth | Q6: 22 | R6: 7 | S6: 2.91 | T6: 0.32 | V6: Byleth | W6: 43 | X6: =W6-Q6 -> 21 | Y6: 15 | Z6: =Y6-R6 -> 8 | AA6: 2.86 | AB6: =AA6-S6 -> -0.05
A7: Mega Man | B7: 36 | C7: 6 | D7: 3.67 | E7: 0.17 | F7: 2.1646511 | G7: ▲1 | H7: Zelda | I7: 19 | J7: 4 | K7: 3.84 | L7: =J7/I7 -> 0.21052632 | M7: 2.587645 | N7: ▼2 | P7: Captain Falcon | Q7: 30 | R7: 5 | S7: 4.3 | T7: 0.17 | V7: Captain Falcon | W7: 31 | X7: =W7-Q7 -> 1 | Y7: 5 | Z7: =Y7-R7 -> 0 | AA7: 4.23 | AB7: =AA7-S7 -> -0.07
A8: Villager | B8: 39 | C8: 13 | D8: 3.72 | E8: 0.33 | F8: 2.5562736 | G8: ▼3 | H8: Pokemon Trainer | I8: 14 | J8: 2 | K8: 3.86 | L8: =J8/I8 -> 0.14285714 | M8: 1.9944979 | N8: ▼2 | P8: Cloud | Q8: 11 | R8: 2 | S8: 4.45 | T8: 0.18 | V8: Cloud | W8: 14 | X8: =W8-Q8 -> 3 | Y8: 2 | Z8: =Y8-R8 -> 0 | AA8: 4.79 | AB8: =AA8-S8 -> 0.34
A9: Pit | B9: 9 | C9: 1 | D9: 3.89 | E9: 0.13 | F9: 2.4209732 | H9: Pit | I9: 9 | J9: 1 | K9: 3.89 | L9: =J9/I9 -> 0.11111111 | M9: 2.4209732 | P9: Corrin | Q9: 33 | R9: 3 | S9: 4.24 | T9: 0.09 | V9: Corrin | W9: 41 | X9: =W9-Q9 -> 8 | Y9: 3 | Z9: =Y9-R9 -> 0 | AA9: 4.46 | AB9: =AA9-S9 -> 0.22
A10: Mii Sword Fighter | B10: 5 | C10: 1 | D10: 4 | E10: 0.2 | F10: 3.2403703 | H10: Falco | I10: 9 | J10: 0 | K10: 4 | L10: =J10/I10 -> 0 | M10: 2.1794495 | N10: ▲13🚀🚀🚀 | P10: Diddy Kong | Q10: 3 | R10: 1 | S10: 5.67 | T10: 0.33 | V10: Diddy Kong | W10: 11 | X10: =W10-Q10 -> 8 | Y10: 1 | Z10: =Y10-R10 -> 0 | AA10: 6.45 | AB10: =AA10-S10 -> 0.78
A11: King Dedede | B11: 71 | C11: 16 | D11: 4.06 | E11: 0.23 | F11: 2.3634038 | H11: Jigglypuff | I11: 17 | J11: 1 | K11: 4 | L11: =J11/I11 -> 0.058823529 | M11: 2.5495098 | N11: ▲3 | P11: Donkey Kong | Q11: 30 | R11: 3 | S11: 5.23 | T11: 0.1 | V11: Donkey Kong | W11: 38 | X11: =W11-Q11 -> 8 | Y11: 3 | Z11: =Y11-R11 -> 0 | AA11: 5.42 | AB11: =AA11-S11 -> 0.19
A12: Wario | B12: 9 | C12: 2 | D12: 4.11 | E12: 0.22 | F12: 2.5712081 | H12: Mii Sword Fighter | I12: 5 | J12: 1 | K12: 4 | L12: =J12/I12 -> 0.2 | M12: 3.2403703 | P12: Dr. Mario | Q12: 3 | R12: 1 | S12: 4.67 | T12: 0 | V12: Dr. Mario | W12: 8 | X12: =W12-Q12 -> 5 | Y12: 1 | Z12: =Y12-R12 -> 0 | AA12: 5.5 | AB12: =AA12-S12 -> 0.83
A13: Link | B13: 6 | C13: 1 | D13: 4.17 | E13: 0.17 | F13: 2.6394444 | H13: Wario | I13: 10 | J13: 2 | K13: 4 | L13: =J13/I13 -> 0.2 | M13: 2.4494897 | N13: ▼1 | P13: Duck Hunt | Q13: 3 | R13: 0 | S13: 4 | T13: 0 | V13: Duck Hunt | W13: 6 | X13: =W13-Q13 -> 3 | Y13: 0 | Z13: =Y13-R13 -> 0 | AA13: 5.67 | AB13: =AA13-S13 -> 1.67
A14: Jigglypuff | B14: 16 | C14: 0 | D14: 4.19 | E14: 0 | F14: 2.5091499 | H14: King Dedede | I14: 72 | J14: 16 | K14: 4.1 | L14: =J14/I14 -> 0.22222222 | M14: 2.369439 | N14: ▼3 | P14: Falco | Q14: 6 | R14: 0 | S14: 3.67 | T14: 0 | V14: Falco | W14: 9 | X14: =W14-Q14 -> 3 | Y14: 0 | Z14: =Y14-R14 -> 0 | AA14: 4 | AB14: =AA14-S14 -> 0.33
A15: Joker | B15: 9 | C15: 2 | D15: 4.2 | E15: 0.25 | F15: 2.7284509 | H15: Link | I15: 6 | J15: 1 | K15: 4.17 | L15: =J15/I15 -> 0.16666667 | M15: 2.6394444 | N15: ▼2 | P15: Fox | Q15: 11 | R15: 1 | S15: 5.82 | T15: 0.09 | V15: Fox | W15: 11 | X15: =W15-Q15 -> 0 | Y15: 1 | Z15: =Y15-R15 -> 0 | AA15: 5.82 | AB15: =AA15-S15 -> 0
A16: Mewtwo | B16: 5 | C16: 0 | D16: 4.2 | E16: 0 | F16: 1.3038405 | H16: Joker | I16: 9 | J16: 2 | K16: 4.2 | L16: =J16/I16 -> 0.22222222 | M16: 2.7284509 | N16: ▼1 | P16: Ganondorf | Q16: 26 | R16: 3 | S16: 5.31 | T16: 0.12 | V16: Ganondorf | W16: 42 | X16: =W16-Q16 -> 16 | Y16: 3 | Z16: =Y16-R16 -> 0 | AA16: 5 | AB16: =AA16-S16 -> -0.31
A17: Sephiroth | B17: 5 | C17: 1 | D17: 4.2 | E17: 0.2 | F17: 2.1679483 | H17: Mewtwo | I17: 5 | J17: 0 | K17: 4.2 | L17: =J17/I17 -> 0 | M17: 1.3038405 | N17: ▼1 | P17: Greninja | Q17: 5 | R17: 1 | S17: 5 | T17: 0.2 | V17: Greninja | W17: 5 | X17: =W17-Q17 -> 0 | Y17: 1 | Z17: =Y17-R17 -> 0 | AA17: 5 | AB17: =AA17-S17 -> 0
A18: Toon Link | B18: 5 | C18: 0 | D18: 4.2 | E18: 0 | F18: 2.4899799 | H18: Sephiroth | I18: 5 | J18: 1 | K18: 4.2 | L18: =J18/I18 -> 0.2 | M18: 2.1679483 | N18: ▼1 | P18: Hero | Q18: 4 | R18: 0 | S18: 4.25 | T18: 0 | V18: Hero | W18: 5 | X18: =W18-Q18 -> 1 | Y18: 0 | Z18: =Y18-R18 -> 0 | AA18: 4.4 | AB18: =AA18-S18 -> 0.15
A19: Captain Falcon | B19: 31 | C19: 5 | D19: 4.23 | E19: 0.16 | F19: 2.4235566 | H19: Toon Link | I19: 5 | J19: 0 | K19: 4.2 | L19: =J19/I19 -> 0 | M19: 2.4899799 | N19: ▼1 | P19: Ice-Climbers | Q19: 3 | R19: 0 | S19: 6 | T19: 0 | V19: Ice-Climbers | W19: 5 | X19: =W19-Q19 -> 2 | Y19: 0 | Z19: =Y19-R19 -> 0 | AA19: 5.2 | AB19: =AA19-S19 -> -0.8
A20: Piranha Plant | B20: 8 | C20: 0 | D20: 4.25 | E20: 0 | F20: 2.0528726 | H20: Captain Falcon | I20: 31 | J20: 5 | K20: 4.23 | L20: =J20/I20 -> 0.16129032 | M20: 2.4994623 | N20: ▼1 | P20: Ike | Q20: 3 | R20: 0 | S20: 4.67 | T20: 0 | V20: Ike | W20: 10 | X20: =W20-Q20 -> 7 | Y20: 0 | Z20: =Y20-R20 -> 0 | AA20: 4.6 | AB20: =AA20-S20 -> -0.07
A21: Samus | B21: 97 | C21: 13 | D21: 4.28 | E21: 0.13 | F21: 2.2035297 | H21: Piranha Plant | I21: 8 | J21: 0 | K21: 4.25 | L21: =J21/I21 -> 0 | M21: 2.0528726 | N21: ▼1 | P21: Incineroar | Q21: 7 | R21: 1 | S21: 4.43 | T21: 0.14 | V21: Incineroar | W21: 8 | X21: =W21-Q21 -> 1 | Y21: 1 | Z21: =Y21-R21 -> 0 | AA21: 4.63 | AB21: =AA21-S21 -> 0.2
A22: Terry | B22: 25 | C22: 5 | D22: 4.28 | E22: 0.2 | F22: 2.1315096 | H22: Samus | I22: 102 | J22: 14 | K22: 4.25 | L22: =J22/I22 -> 0.1372549 | M22: 2.2045689 | N22: ▼1 | P22: Inkling | Q22: 3 | R22: 0 | S22: 4 | T22: 0 | V22: Inkling | W22: 5 | X22: =W22-Q22 -> 2 | Y22: 0 | Z22: =Y22-R22 -> 0 | AA22: 4.4 | AB22: =AA22-S22 -> 0.4
A23: Falco | B23: 7 | C23: 0 | D23: 4.29 | E23: 0 | F23: 2.3603874 | H23: Terry | I23: 25 | J23: 5 | K23: 4.28 | L23: =J23/I23 -> 0.2 | M23: 2.1315096 | N23: ▼1 | P23: Isabelle | Q23: 7 | R23: 3 | S23: 3.29 | T23: 0.43 | V23: Isabelle | W23: 10 | X23: =W23-Q23 -> 3 | Y23: 3 | Z23: =Y23-R23 -> 0 | AA23: 4.3 | AB23: =AA23-S23 -> 1.01
A24: Kirby | B24: 28 | C24: 4 | D24: 4.29 | E24: 0.14 | F24: 2.208689 | H24: Kirby | I24: 28 | J24: 4 | K24: 4.29 | L24: =J24/I24 -> 0.14285714 | M24: 2.208689 | P24: Jigglypuff | Q24: 13 | R24: 0 | S24: 4.62 | T24: 0 | V24: Jigglypuff | W24: 17 | X24: =W24-Q24 -> 4 | Y24: 1 | Z24: =Y24-R24 -> 1 | AA24: 4 | AB24: =AA24-S24 -> -0.62
A25: Isabelle | B25: 10 | C25: 3 | D25: 4.3 | E25: 0.3 | F25: 2.7100635 | H25: Isabelle | I25: 10 | J25: 3 | K25: 4.3 | L25: =J25/I25 -> 0.3 | M25: 2.7100635 | P25: Joker | Q25: 8 | R25: 2 | S25: 4.5 | T25: 0.25 | V25: Joker | W25: 9 | X25: =W25-Q25 -> 1 | Y25: 2 | Z25: =Y25-R25 -> 0 | AA25: 4.2 | AB25: =AA25-S25 -> -0.3
A26: Ness | B26: 38 | C26: 4 | D26: 4.32 | E26: 0.11 | F26: 2.1683144 | G26: ▲1 | H26: Lucas | I26: 6 | J26: 0 | K26: 4.33 | L26: =J26/I26 -> 0 | M26: 2.2509257 | N26: ▲1 | P26: Kazuya | Q26: 3 | R26: 1 | S26: 3.33 | T26: 0.33 | V26: Kazuya | W26: 6 | X26: =W26-Q26 -> 3 | Y26: 1 | Z26: =Y26-R26 -> 0 | AA26: 3.5 | AB26: =AA26-S26 -> 0.17
A27: Lucas | B27: 6 | C27: 0 | D27: 4.33 | E27: 0 | F27: 2.2509257 | H27: Palutena | I27: 6 | J27: 0 | K27: 4.33 | L27: =J27/I27 -> 0 | M27: 2.3380904 | N27: ▲1 | P27: Ken | Q27: 9 | R27: 0 | S27: 6.11 | T27: 0 | V27: Ken | W27: 12 | X27: =W27-Q27 -> 3 | Y27: 1 | Z27: =Y27-R27 -> 1 | AA27: 5.83 | AB27: =AA27-S27 -> -0.28
A28: Palutena | B28: 6 | C28: 0 | D28: 4.33 | E28: 0 | F28: 2.3380904 | H28: Wii Fit Trainer | I28: 6 | J28: 0 | K28: 4.33 | L28: =J28/I28 -> 0 | M28: 1.6329932 | N28: ▲1 | P28: King Dedede | Q28: 61 | R28: 13 | S28: 4.11 | T28: 0.21 | V28: King Dedede | W28: 72 | X28: =W28-Q28 -> 11 | Y28: 16 | Z28: =Y28-R28 -> 3 | AA28: 4.1 | AB28: =AA28-S28 -> -0.01
A29: Wii Fit Trainer | B29: 6 | C29: 0 | D29: 4.33 | E29: 0 | F29: 1.6329932 | H29: Bayonetta | I29: 25 | J29: 2 | K29: 4.4 | L29: =J29/I29 -> 0.08 | M29: 2.3273733 | N29: ▲5🚀 | P29: King K Rool | Q29: 10 | R29: 1 | S29: 5 | T29: 0.1 | V29: King K Rool | W29: 20 | X29: =W29-Q29 -> 10 | Y29: 1 | Z29: =Y29-R29 -> 0 | AA29: 4.95 | AB29: =AA29-S29 -> -0.05
A30: Pikachu | B30: 18 | C30: 1 | D30: 4.39 | E30: 0.06 | F30: 2.1458274 | H30: Hero | I30: 5 | J30: 0 | K30: 4.4 | L30: =J30/I30 -> 0 | M30: 1.9493589 | N30: ▲1 | P30: Kirby | Q30: 24 | R30: 3 | S30: 4.29 | T30: 0.13 | V30: Kirby | W30: 28 | X30: =W30-Q30 -> 4 | Y30: 4 | Z30: =Y30-R30 -> 1 | AA30: 4.29 | AB30: =AA30-S30 -> 0
A31: Hero | B31: 5 | C31: 0 | D31: 4.4 | E31: 0 | F31: 1.9493589 | H31: Inkling | I31: 5 | J31: 0 | K31: 4.4 | L31: =J31/I31 -> 0 | M31: 2.607681 | N31: ▲1 | P31: Link | Q31: 6 | R31: 1 | S31: 4.17 | T31: 0.17 | V31: Link | W31: 6 | X31: =W31-Q31 -> 0 | Y31: 1 | Z31: =Y31-R31 -> 0 | AA31: 4.17 | AB31: =AA31-S31 -> 0
A32: Inkling | B32: 5 | C32: 0 | D32: 4.4 | E32: 0 | F32: 2.607681 | H32: Pikachu | I32: 20 | J32: 1 | K32: 4.4 | L32: =J32/I32 -> 0.05 | M32: 2.0875571 | N32: ▼2 | P32: Little Mac | Q32: 3 | R32: 0 | S32: 5.33 | T32: 0 | V32: Little Mac | W32: 9 | X32: =W32-Q32 -> 6 | Y32: 0 | Z32: =Y32-R32 -> 0 | AA32: 6.11 | AB32: =AA32-S32 -> 0.78
